<mujoco model="inspire_hand_r">
  <compiler angle="radian" autolimits="true" meshdir="meshes"/>
  <statistic meansize="0.0283996" extent="0.249469" center="0.423052 0.511898 0.748973"/>
  <default>
    <default class="base">
        <joint axis="0 0 1" range="-0.47 0.47"/>
        <position ctrlrange="-0.47 0.47"/>
    </default>
    <default class="proximal">
      <joint range="-0.196 1.61"/>
      <position ctrlrange="-0.196 1.61"/>
    </default>
    <default class="medial">
      <joint range="-0.174 1.709"/>
      <position ctrlrange="-0.174 1.709"/>
    </default>
    <default class="distal">
      <joint range="-0.227 1.618"/>
      <position ctrlrange="-0.227 1.618"/>
    </default>
    <default class="thumb_base">
        <joint range="0.263 1.396"/>
        <position ctrlrange="0 3.14" kp="0.5"/>
    </default>
    <default class="right_hand">
      <joint damping="0.05" armature="0.0002" frictionloss="0.01"/>
    </default>
  </default>
  
  <asset>
    <mesh name="R_hand_base_link" file="R_hand_base_link.STL"/>
    <mesh name="R_thumb_proximal_base" file="R_thumb_proximal_base.STL"/>
    <mesh name="R_thumb_proximal" file="R_thumb_proximal.STL"/>
    <mesh name="R_thumb_intermediate" file="R_thumb_intermediate.STL"/>
    <mesh name="R_thumb_distal" file="R_thumb_distal.STL"/>
    <mesh name="R_index_proximal" file="R_index_proximal.STL"/>
    <mesh name="R_index_distal" file="R_index_distal.STL"/>
    <mesh name="R_middle_proximal" file="R_middle_proximal.STL"/>
    <mesh name="R_middle_distal" file="R_middle_distal.STL"/>
    <mesh name="R_ring_proximal" file="R_ring_proximal.STL"/>
    <mesh name="R_ring_distal" file="R_ring_distal.STL"/>
    <mesh name="R_pinky_proximal" file="R_pinky_proximal.STL"/>
    <mesh name="R_pinky_distal" file="R_pinky_distal.STL"/>
  </asset>
  <worldbody>
  <body childclass="right_hand">
    <body name="R_hand_base">
    <geom pos="0.5 0.5 0.5" quat="0.707107 -0.707107 0 0" type="mesh" rgba="1 1 1 1" mesh="R_hand_base_link"/>
    </body>
    <body name="R_thumb_proximal_base" pos="0.401367 0.488636 0.73173" quat="0.990013 1.83152e-06 -0.140974 2.57024e-07">
      <inertial pos="-0.0048772 -0.010163 0.00044069" quat="0.075637 0.631378 -0.107678 0.764229" mass="0.0018869" diaginertia="8.66028e-08 6.87321e-08 4.94192e-08"/>
      <joint name="R_thumb_MCP_joint1" pos="0 0 0" axis="0 -1 0" range="0.2 1.3"/>
      <geom type="mesh" rgba="1 1 1 1" mesh="R_thumb_proximal_base"/>
      <body name="R_thumb_proximal" pos="-0.0115 -0.011843 0" quat="0.624568 0.331531 0.624571 -0.331532">
        <inertial pos="-3.8592e-05 0.02533 -0.0017007" quat="0.656826 0.754039 0.00146914 -0.00128614" mass="0.0066075" diaginertia="2.78601e-06 2.43932e-06 8.64597e-07"/>
        <joint name="R_thumb_MCP_joint2" pos="0 0 0" axis="-1 0 0" range="1.3 1.8"/>
        <geom type="mesh" rgba="1 1 1 1" mesh="R_thumb_proximal"/>
        <body name="R_thumb_intermediate" pos="0 0.055863 0.0039241" quat="0.999817 -0.0191483 0 0">
          <inertial pos="2.8437e-07 0.0072526 -0.0064293" quat="0.575988 0.817458 -0.000107087 6.96147e-05" mass="0.0037847" diaginertia="4.6531e-07 4.48088e-07 2.45662e-07"/>
          <joint name="R_thumb_PIP_joint" pos="0 0 0" axis="1 0 0" range="0 1"/>
          <geom type="mesh" rgba="1 1 1 1" mesh="R_thumb_intermediate"/>
          <body name="R_thumb_distal" pos="0 0.022558 -0.0020717" quat="0.999983 -0.00582097 0 0">
            <inertial pos="-3.3054e-06 0.010511 -0.00057863" quat="0.624404 0.781098 0.00147531 -0.00199963" mass="0.0033441" diaginertia="2.0026e-07 1.95252e-07 8.15973e-08"/>
            <joint name="R_thumb_DIP_joint" pos="0 0 0" axis="1 0 0" range="0 1.2"/>
            <geom type="mesh" rgba="1 1 1 1" mesh="R_thumb_distal"/>
          </body>
        </body>
      </body>
    </body>
    <body name="R_index_proximal" pos="0.405441 0.554025 0.74897" quat="-0.00212755 -0.0173224 0.992416 0.121677">
      <inertial pos="0.0099008 0.011884 0.0016958" quat="0.629448 0.777042 2.20645e-05 -2.45535e-05" mass="0.0042403" diaginertia="6.9398e-07 6.62877e-07 2.10913e-07"/>
      <joint name="R_index_MCP_joint" pos="0 0 0" axis="1 0 0" range="0 1.7"/>
      <geom type="mesh" rgba="1 1 1 1" mesh="R_index_proximal"/>
      <body name="R_index_distal" pos="0.001575 0.030445 0.010275" quat="0.999755 0.0221422 0 0">
        <inertial pos="0.0083258 0.019591 0.0019565" quat="0.581929 0.813239 4.32051e-07 6.03786e-07" mass="0.0045683" diaginertia="7.8179e-07 7.72465e-07 8.47248e-08"/>
        <joint name="R_index_DIP_joint" pos="0 0 0" axis="1 0 0" range="0 1.6"/>
        <geom type="mesh" rgba="1 1 1 1" mesh="R_index_distal"/>
      </body>
    </body>
    <body name="R_middle_proximal" pos="0.422932 0.554042 0.74897" quat="-3.64455e-06 4.57949e-07 0.992198 0.124673">
      <inertial pos="0.008065 0.011884 0.0016958" quat="0.629448 0.777042 2.15784e-05 -2.62734e-05" mass="0.0042403" diaginertia="6.9397e-07 6.62866e-07 2.10914e-07"/>
      <joint name="R_middle_MCP_joint" pos="0 0 0" axis="1 0 0" range="0 1.7"/>
      <geom type="mesh" rgba="1 1 1 1" mesh="R_middle_proximal"/>
      <body name="R_middle_distal" pos="0.0016673 0.030445 0.010275" quat="0.999363 0.0356989 0 0">
        <inertial pos="0.0063978 0.020807 0.0018039" quat="0.589614 0.807685 -6.23875e-05 4.98373e-05" mass="0.0050396" diaginertia="9.8384e-07 9.73281e-07 9.13985e-08"/>
        <joint name="R_middle_DIP_joint" pos="0 0 0" axis="1 0 0" range="0 1.6"/>
        <geom type="mesh" rgba="1 1 1 1" mesh="R_middle_distal"/>
      </body>
    </body>
    <body name="R_ring_proximal" pos="0.442106 0.553119 0.74897" quat="0.00325992 0.0259732 0.991858 0.12463">
      <inertial pos="0.0080207 0.011884 0.0016959" quat="0.629449 0.777042 1.88154e-05 -2.40552e-05" mass="0.0042403" diaginertia="6.9397e-07 6.62866e-07 2.10914e-07"/>
      <joint name="R_ring_MCP_joint" pos="0 0 0" axis="1 0 0" range="0 1.7"/>
      <geom type="mesh" rgba="1 1 1 1" mesh="R_ring_proximal"/>
      <body name="R_ring_distal" pos="0 0.030445 0.010275" quat="0.999803 0.0198727 0 0">
        <inertial pos="0.0080209 0.019591 0.0019565" quat="0.581926 0.813242 0 0" mass="0.0045683" diaginertia="7.8177e-07 7.72447e-07 8.47227e-08"/>
        <joint name="R_ring_DIP_joint" pos="0 0 0" axis="1 0 0" range="0 1.6"/>
        <geom type="mesh" rgba="1 1 1 1" mesh="R_ring_distal"/>
      </body>
    </body>
    <body name="R_pinky_proximal" pos="0.461118 0.551205 0.74897" quat="-0.00652853 -0.0519273 -0.990838 -0.124502">
      <inertial pos="0.0078887 0.011884 0.0016959" quat="0.629449 0.777042 2.01737e-05 -2.54775e-05" mass="0.0042403" diaginertia="6.9397e-07 6.62866e-07 2.10914e-07"/>
      <joint name="R_pinky_MCP_joint" pos="0 0 0" axis="1 0 0" range="0 1.7"/>
      <geom type="mesh" rgba="1 1 1 1" mesh="R_pinky_proximal"/>
      <body name="R_pinky_distal" pos="0 0.030445 0.010275" quat="0.999822 -0.0188444 0 0">
        <inertial pos="0.0078857 0.016239 0.0022243" quat="0.553304 0.832968 0.0036878 -0.00236477" mass="0.0035996" diaginertia="4.4867e-07 4.43716e-07 6.56536e-08"/>
        <joint name="R_pinky_DIP_joint" pos="0 0 0" axis="1 0 0" range="0 1.6"/>
        <geom type="mesh" rgba="1 1 1 1" mesh="R_pinky_distal"/>
      </body>
    </body>
  </body>
  </worldbody>


  <contact>
    <exclude body1="R_hand_base" body2="R_index_proximal"/>
    <exclude body1="R_hand_base" body2="R_middle_proximal"/>
    <exclude body1="R_hand_base" body2="R_ring_proximal"/>
    <exclude body1="R_hand_base" body2="R_pinky_proximal"/>
  </contact>



  <tendon>
    <fixed name="index_tendon" limited="true" range="-0.001 0.001">
        <joint joint="R_index_MCP_joint" coef="1"/>
        <joint joint="R_index_DIP_joint" coef="-1" />
    </fixed>
    <fixed name="middle_tendon" limited="true" range="-0.001 0.001">
        <joint joint="R_middle_MCP_joint" coef="1"/>
        <joint joint="R_middle_DIP_joint" coef="-1" />
    </fixed>
    <fixed name="ring_tendon" limited="true" range="-0.001 0.001">
        <joint joint="R_ring_MCP_joint" coef="1"/>
        <joint joint="R_ring_DIP_joint" coef="-1" />
    </fixed>
    <fixed name="pinky_tendon" limited="true" range="-0.001 0.001">
        <joint joint="R_pinky_MCP_joint" coef="1"/>
        <joint joint="R_pinky_DIP_joint" coef="-1" />
    </fixed>
  </tendon>

  <actuator>
    <position name="index_tendon_a" joint="R_index_MCP_joint" class="thumb_base"/>
    <position name="middle_tendon_a" joint="R_middle_MCP_joint" class="thumb_base"/>
    <position name="ring_tendon_a" joint="R_ring_MCP_joint" class="thumb_base"/>
    <position name="pinky_tendon_a" joint="R_pinky_MCP_joint" class="thumb_base"/>
  </actuator>

</mujoco>
