<mujoco model="inspire_hand_l">
  <compiler angle="radian" autolimits="true"/>
  <statistic meansize="0.0283931" extent="0.247796" center="0.407549 0.301148 0.748959"/>
  <asset>
    <mesh name="L_hand_base_link" file="L_hand_base_link.STL"/>
    <mesh name="L_thumb_proximal_base" file="L_thumb_proximal_base.STL"/>
    <mesh name="L_thumb_proximal" file="L_thumb_proximal.STL"/>
    <mesh name="L_thumb_intermediate" file="L_thumb_intermediate.STL"/>
    <mesh name="L_thumb_distal" file="L_thumb_distal.STL"/>
    <mesh name="L_index_proximal" file="L_index_proximal.STL"/>
    <mesh name="L_index_distal" file="L_index_distal.STL"/>
    <mesh name="L_middle_proximal" file="L_middle_proximal.STL"/>
    <mesh name="L_middle_distal" file="L_middle_distal.STL"/>
    <mesh name="L_ring_proximal" file="L_ring_proximal.STL"/>
    <mesh name="L_ring_distal" file="L_ring_distal.STL"/>
    <mesh name="L_pinky_proximal" file="L_pinky_proximal.STL"/>
    <mesh name="L_pinky_distal" file="L_pinky_distal.STL"/>
  </asset>
  <worldbody>
    <geom pos="0.5 0.5 0.5" quat="0.707107 -0.707107 0 0" type="mesh" rgba="1 1 1 1" mesh="L_hand_base_link"/>
    <body name="L_thumb_proximal_base" pos="0.401367 0.34174 0.73173" quat="-1.81667e-06 -0.996416 1.56498e-07 -0.0845938">
      <inertial pos="-0.0048772 0.00668 -0.00044071" quat="0.107679 0.764233 -0.0756348 0.631373" mass="0.0018869" diaginertia="8.66029e-08 6.87331e-08 4.942e-08"/>
      <joint name="L_thumb_MCP_joint1" pos="0 0 0" axis="0 1 0" range="0.3 1.4"/>
      <geom type="mesh" rgba="1 1 1 1" mesh="L_thumb_proximal_base"/>
      <body name="L_thumb_proximal" pos="-0.0115 0.005 0" quat="0.331531 0.624568 -0.331533 0.62457">
        <inertial pos="-3.8578e-05 0.025335 0.0016982" quat="0.754084 0.656775 -0.00128576 0.0014545" mass="0.0066101" diaginertia="2.78701e-06 2.44019e-06 8.64653e-07"/>
        <joint name="L_thumb_MCP_joint2" pos="0 0 0" axis="-1 0 0" range="1.5 2"/>
        <geom type="mesh" rgba="1 1 1 1" mesh="L_thumb_proximal"/>
        <body name="L_thumb_intermediate" pos="0 0.055863 -0.0039241" quat="0.999817 0.0191483 0 0">
          <inertial pos="-1.7401e-07 0.0072516 0.0064286" quat="0.81744 0.576014 6.61106e-05 -9.38198e-05" mass="0.0037844" diaginertia="4.6532e-07 4.48115e-07 2.45645e-07"/>
          <joint name="L_thumb_PIP_joint" pos="0 0 0" axis="-1 0 0" range="0 1"/>
          <geom type="mesh" rgba="1 1 1 1" mesh="L_thumb_intermediate"/>
          <body name="L_thumb_distal" pos="0 0.022558 0.0020717" quat="0.999983 0.00582097 0 0">
            <inertial pos="-3.3076e-06 0.010511 0.00057861" quat="0.781092 0.624411 -0.00196986 0.00144874" mass="0.003344" diaginertia="2.0026e-07 1.95251e-07 8.15962e-08"/>
            <joint name="L_thumb_DIP_joint" pos="0 0 0" axis="-1 0 0" range="0 1.2"/>
            <geom type="mesh" rgba="1 1 1 1" mesh="L_thumb_distal"/>
          </body>
        </body>
      </body>
    </body>
    <body name="L_index_proximal" pos="0.403586 0.25993 0.74897" quat="0.017316 0.00217951 0.124654 0.992047">
      <inertial pos="0.0080456 0.011884 -0.0016957" quat="0.777057 0.62943 1.19165e-05 9.6526e-06" mass="0.0042405" diaginertia="6.9402e-07 6.62906e-07 2.10924e-07"/>
      <joint name="L_index_MCP_joint" pos="0 0 0" axis="-1 0 0" range="0 1.7"/>
      <geom type="mesh" rgba="1 1 1 1" mesh="L_index_proximal"/>
      <body name="L_index_distal" pos="0.0016538 0.030445 -0.010275" quat="0.999803 -0.0198727 0 0">
        <inertial pos="0.0063917 0.01959 -0.0019564" quat="0.813238 0.581931 0 0" mass="0.0045682" diaginertia="7.8176e-07 7.72431e-07 8.47188e-08"/>
        <joint name="L_index_DIP_joint" pos="0 0 0" axis="-1 0 0" range="0 1.6"/>
        <geom type="mesh" rgba="1 1 1 1" mesh="L_index_distal"/>
      </body>
    </body>
    <body name="L_middle_proximal" pos="0.422932 0.25984 0.74897" quat="-4.57949e-07 3.64455e-06 0.124673 0.992198">
      <inertial pos="0.0080653 0.011884 -0.0016957" quat="0.777057 0.62943 1.16794e-05 9.46051e-06" mass="0.0042405" diaginertia="6.9402e-07 6.62906e-07 2.10924e-07"/>
      <joint name="L_middle_MCP_joint" pos="0 0 0" axis="-1 0 0" range="0 1.7"/>
      <geom type="mesh" rgba="1 1 1 1" mesh="L_middle_proximal"/>
      <body name="L_middle_distal" pos="0.0016698 0.030445 -0.010275" quat="0.999363 -0.0356989 0 0">
        <inertial pos="0.0063955 0.020807 -0.0018039" quat="0.807684 0.589615 7.8918e-05 -0.000111289" mass="0.0050397" diaginertia="9.8385e-07 9.73291e-07 9.13995e-08"/>
        <joint name="L_middle_DIP_joint" pos="0 0 0" axis="-1 0 0" range="0 1.6"/>
        <geom type="mesh" rgba="1 1 1 1" mesh="L_middle_distal"/>
      </body>
    </body>
    <body name="L_ring_proximal" pos="0.444902 0.26091 0.74897" quat="-0.0259732 -0.00325992 0.12463 0.991858">
      <inertial pos="0.010821 0.011884 -0.0016957" quat="0.777057 0.62943 1.13816e-05 9.21931e-06" mass="0.0042405" diaginertia="6.9402e-07 6.62906e-07 2.10924e-07"/>
      <joint name="L_ring_MCP_joint" pos="0 0 0" axis="-1 0 0" range="0 1.7"/>
      <geom type="mesh" rgba="1 1 1 1" mesh="L_ring_proximal"/>
      <body name="L_ring_distal" pos="0.0015355 0.030445 -0.010275" quat="0.999803 -0.0198727 0 0">
        <inertial pos="0.009285 0.019591 -0.0019565" quat="0.813238 0.581931 0 0" mass="0.0045682" diaginertia="7.8176e-07 7.72431e-07 8.47188e-08"/>
        <joint name="L_ring_DIP_joint" pos="0 0 0" axis="-1 0 0" range="0 1.6"/>
        <geom type="mesh" rgba="1 1 1 1" mesh="L_ring_distal"/>
      </body>
    </body>
    <body name="L_pinky_proximal" pos="0.466744 0.26327 0.74897" quat="-0.0519282 -0.00652125 0.124502 0.990838">
      <inertial pos="0.013546 0.011884 -0.0016957" quat="0.777057 0.62943 1.15068e-05 9.32075e-06" mass="0.0042405" diaginertia="6.9402e-07 6.62906e-07 2.10924e-07"/>
      <joint name="L_pinky_MCP_joint" pos="0 0 0" axis="-1 0 0" range="0 1.7"/>
      <geom type="mesh" rgba="1 1 1 1" mesh="L_pinky_proximal"/>
      <body name="L_pinky_distal" pos="0 0.030445 -0.010275" quat="0.999822 0.0188444 0 0">
        <inertial pos="0.013546 0.016245 -0.0022219" quat="0.832929 0.553379 -3.53e-06 -2.34525e-06" mass="0.0036036" diaginertia="4.4881e-07 4.43813e-07 6.57372e-08"/>
        <joint name="L_pinky_DIP_joint" pos="0 0 0" axis="-1 0 0" range="0 1.6"/>
        <geom type="mesh" rgba="1 1 1 1" mesh="L_pinky_distal"/>
      </body>
    </body>
  </worldbody>
</mujoco>
